2023-02-02 10:10:31,006 |                  flt |    ERROR | Traceback (most recent call last):
  File "/usr/local/lib/python3.8/dist-packages/foliant/cli/make.py", line 110, in get_config
    config = Parser(project_path, config_file_name, self.logger, quiet).parse()
  File "/usr/local/lib/python3.8/dist-packages/foliant/config/base.py", line 38, in parse
    config = {**self._defaults, **load(config_file, Loader)}
  File "/usr/local/lib/python3.8/dist-packages/yaml/__init__.py", line 114, in load
    return loader.get_single_data()
  File "/usr/local/lib/python3.8/dist-packages/yaml/constructor.py", line 51, in get_single_data
    return self.construct_document(node)
  File "/usr/local/lib/python3.8/dist-packages/yaml/constructor.py", line 60, in construct_document
    for dummy in generator:
  File "/usr/local/lib/python3.8/dist-packages/yaml/constructor.py", line 413, in construct_yaml_map
    value = self.construct_mapping(node)
  File "/usr/local/lib/python3.8/dist-packages/yaml/constructor.py", line 218, in construct_mapping
    return super().construct_mapping(node, deep=deep)
  File "/usr/local/lib/python3.8/dist-packages/yaml/constructor.py", line 143, in construct_mapping
    value = self.construct_object(value_node, deep=deep)
  File "/usr/local/lib/python3.8/dist-packages/yaml/constructor.py", line 100, in construct_object
    data = constructor(self, node)
  File "/usr/local/lib/python3.8/dist-packages/foliant/config/path.py", line 16, in _resolve_path_tag
    return (self.project_path / path).resolve(strict=True).as_posix()
  File "/usr/lib/python3.8/pathlib.py", line 1181, in resolve
    s = self._flavour.resolve(self, strict=strict)
  File "/usr/lib/python3.8/pathlib.py", line 363, in resolve
    return _resolve(base, str(path)) or sep
  File "/usr/lib/python3.8/pathlib.py", line 347, in _resolve
    target = accessor.readlink(newpath)
  File "/usr/lib/python3.8/pathlib.py", line 452, in readlink
    return os.readlink(path)
FileNotFoundError: [Errno 2] No such file or directory: '/usr/src/app/templates'

The above exception was the direct cause of the following exception:

Traceback (most recent call last):
  File "/usr/local/lib/python3.8/dist-packages/foliant/utils.py", line 158, in spinner
    yield
  File "/usr/local/lib/python3.8/dist-packages/foliant/cli/make.py", line 114, in get_config
    raise FileNotFoundError(f'{exception} not found') from  exception
FileNotFoundError: [Errno 2] No such file or directory: '/usr/src/app/templates' not found

2023-02-02 10:10:31,011 |                  flt | CRITICAL | Config parsing failed.
